2024-07-02 19:15:02,981 INFO: Microblog startup [in /Users/erickkendall/Desktop/flask-study/microblog/app/__init__.py:44]
2024-07-02 19:16:46,735 ERROR: Exception on /edit_profile [POST] [in /Users/erickkendall/.pyenv/versions/3.10.2/envs/microblog/lib/python3.10/site-packages/flask/app.py:838]
Traceback (most recent call last):
  File "/Users/erickkendall/.pyenv/versions/3.10.2/envs/microblog/lib/python3.10/site-packages/sqlalchemy/engine/base.py", line 1967, in _exec_single_context
    self.dialect.do_execute(
  File "/Users/erickkendall/.pyenv/versions/3.10.2/envs/microblog/lib/python3.10/site-packages/sqlalchemy/engine/default.py", line 924, in do_execute
    cursor.execute(statement, parameters)
sqlite3.IntegrityError: UNIQUE constraint failed: user.username

The above exception was the direct cause of the following exception:

Traceback (most recent call last):
  File "/Users/erickkendall/.pyenv/versions/3.10.2/envs/microblog/lib/python3.10/site-packages/flask/app.py", line 1473, in wsgi_app
    response = self.full_dispatch_request()
  File "/Users/erickkendall/.pyenv/versions/3.10.2/envs/microblog/lib/python3.10/site-packages/flask/app.py", line 882, in full_dispatch_request
    rv = self.handle_user_exception(e)
  File "/Users/erickkendall/.pyenv/versions/3.10.2/envs/microblog/lib/python3.10/site-packages/flask/app.py", line 880, in full_dispatch_request
    rv = self.dispatch_request()
  File "/Users/erickkendall/.pyenv/versions/3.10.2/envs/microblog/lib/python3.10/site-packages/flask/app.py", line 865, in dispatch_request
    return self.ensure_sync(self.view_functions[rule.endpoint])(**view_args)  # type: ignore[no-any-return]
  File "/Users/erickkendall/.pyenv/versions/3.10.2/envs/microblog/lib/python3.10/site-packages/flask_login/utils.py", line 290, in decorated_view
    return current_app.ensure_sync(func)(*args, **kwargs)
  File "/Users/erickkendall/Desktop/flask-study/microblog/app/routes.py", line 90, in edit_profile
    db.session.commit()
  File "/Users/erickkendall/.pyenv/versions/3.10.2/envs/microblog/lib/python3.10/site-packages/sqlalchemy/orm/scoping.py", line 597, in commit
    return self._proxied.commit()
  File "/Users/erickkendall/.pyenv/versions/3.10.2/envs/microblog/lib/python3.10/site-packages/sqlalchemy/orm/session.py", line 2017, in commit
    trans.commit(_to_root=True)
  File "<string>", line 2, in commit
  File "/Users/erickkendall/.pyenv/versions/3.10.2/envs/microblog/lib/python3.10/site-packages/sqlalchemy/orm/state_changes.py", line 139, in _go
    ret_value = fn(self, *arg, **kw)
  File "/Users/erickkendall/.pyenv/versions/3.10.2/envs/microblog/lib/python3.10/site-packages/sqlalchemy/orm/session.py", line 1302, in commit
    self._prepare_impl()
  File "<string>", line 2, in _prepare_impl
  File "/Users/erickkendall/.pyenv/versions/3.10.2/envs/microblog/lib/python3.10/site-packages/sqlalchemy/orm/state_changes.py", line 139, in _go
    ret_value = fn(self, *arg, **kw)
  File "/Users/erickkendall/.pyenv/versions/3.10.2/envs/microblog/lib/python3.10/site-packages/sqlalchemy/orm/session.py", line 1277, in _prepare_impl
    self.session.flush()
  File "/Users/erickkendall/.pyenv/versions/3.10.2/envs/microblog/lib/python3.10/site-packages/sqlalchemy/orm/session.py", line 4341, in flush
    self._flush(objects)
  File "/Users/erickkendall/.pyenv/versions/3.10.2/envs/microblog/lib/python3.10/site-packages/sqlalchemy/orm/session.py", line 4476, in _flush
    with util.safe_reraise():
  File "/Users/erickkendall/.pyenv/versions/3.10.2/envs/microblog/lib/python3.10/site-packages/sqlalchemy/util/langhelpers.py", line 146, in __exit__
    raise exc_value.with_traceback(exc_tb)
  File "/Users/erickkendall/.pyenv/versions/3.10.2/envs/microblog/lib/python3.10/site-packages/sqlalchemy/orm/session.py", line 4437, in _flush
    flush_context.execute()
  File "/Users/erickkendall/.pyenv/versions/3.10.2/envs/microblog/lib/python3.10/site-packages/sqlalchemy/orm/unitofwork.py", line 466, in execute
    rec.execute(self)
  File "/Users/erickkendall/.pyenv/versions/3.10.2/envs/microblog/lib/python3.10/site-packages/sqlalchemy/orm/unitofwork.py", line 642, in execute
    util.preloaded.orm_persistence.save_obj(
  File "/Users/erickkendall/.pyenv/versions/3.10.2/envs/microblog/lib/python3.10/site-packages/sqlalchemy/orm/persistence.py", line 85, in save_obj
    _emit_update_statements(
  File "/Users/erickkendall/.pyenv/versions/3.10.2/envs/microblog/lib/python3.10/site-packages/sqlalchemy/orm/persistence.py", line 912, in _emit_update_statements
    c = connection.execute(
  File "/Users/erickkendall/.pyenv/versions/3.10.2/envs/microblog/lib/python3.10/site-packages/sqlalchemy/engine/base.py", line 1418, in execute
    return meth(
  File "/Users/erickkendall/.pyenv/versions/3.10.2/envs/microblog/lib/python3.10/site-packages/sqlalchemy/sql/elements.py", line 515, in _execute_on_connection
    return connection._execute_clauseelement(
  File "/Users/erickkendall/.pyenv/versions/3.10.2/envs/microblog/lib/python3.10/site-packages/sqlalchemy/engine/base.py", line 1640, in _execute_clauseelement
    ret = self._execute_context(
  File "/Users/erickkendall/.pyenv/versions/3.10.2/envs/microblog/lib/python3.10/site-packages/sqlalchemy/engine/base.py", line 1846, in _execute_context
    return self._exec_single_context(
  File "/Users/erickkendall/.pyenv/versions/3.10.2/envs/microblog/lib/python3.10/site-packages/sqlalchemy/engine/base.py", line 1986, in _exec_single_context
    self._handle_dbapi_exception(
  File "/Users/erickkendall/.pyenv/versions/3.10.2/envs/microblog/lib/python3.10/site-packages/sqlalchemy/engine/base.py", line 2353, in _handle_dbapi_exception
    raise sqlalchemy_exception.with_traceback(exc_info[2]) from e
  File "/Users/erickkendall/.pyenv/versions/3.10.2/envs/microblog/lib/python3.10/site-packages/sqlalchemy/engine/base.py", line 1967, in _exec_single_context
    self.dialect.do_execute(
  File "/Users/erickkendall/.pyenv/versions/3.10.2/envs/microblog/lib/python3.10/site-packages/sqlalchemy/engine/default.py", line 924, in do_execute
    cursor.execute(statement, parameters)
sqlalchemy.exc.IntegrityError: (sqlite3.IntegrityError) UNIQUE constraint failed: user.username
[SQL: UPDATE user SET username=?, about_me=? WHERE user.id = ?]
[parameters: ('ted', 'test two', 1)]
(Background on this error at: https://sqlalche.me/e/20/gkpj)
2024-07-02 19:27:58,760 INFO: Microblog startup [in /Users/erickkendall/Desktop/flask-study/microblog/app/__init__.py:44]
2024-07-08 15:18:16,801 INFO: Microblog startup [in /Users/erickkendall/Desktop/flask-study/microblog/app/__init__.py:44]
