2024-07-12 11:19:24,539 ERROR: Exception on /login [POST] [in /Users/erickkendall/.pyenv/versions/3.10.2/envs/microblog/lib/python3.10/site-packages/flask/app.py:838]
Traceback (most recent call last):
  File "/Users/erickkendall/.pyenv/versions/3.10.2/envs/microblog/lib/python3.10/site-packages/sqlalchemy/engine/base.py", line 1967, in _exec_single_context
    self.dialect.do_execute(
  File "/Users/erickkendall/.pyenv/versions/3.10.2/envs/microblog/lib/python3.10/site-packages/sqlalchemy/engine/default.py", line 924, in do_execute
    cursor.execute(statement, parameters)
sqlite3.OperationalError: no such table: user

The above exception was the direct cause of the following exception:

Traceback (most recent call last):
  File "/Users/erickkendall/.pyenv/versions/3.10.2/envs/microblog/lib/python3.10/site-packages/flask/app.py", line 1473, in wsgi_app
    response = self.full_dispatch_request()
  File "/Users/erickkendall/.pyenv/versions/3.10.2/envs/microblog/lib/python3.10/site-packages/flask/app.py", line 882, in full_dispatch_request
    rv = self.handle_user_exception(e)
  File "/Users/erickkendall/.pyenv/versions/3.10.2/envs/microblog/lib/python3.10/site-packages/flask/app.py", line 880, in full_dispatch_request
    rv = self.dispatch_request()
  File "/Users/erickkendall/.pyenv/versions/3.10.2/envs/microblog/lib/python3.10/site-packages/flask/app.py", line 865, in dispatch_request
    return self.ensure_sync(self.view_functions[rule.endpoint])(**view_args)  # type: ignore[no-any-return]
  File "/Users/erickkendall/Desktop/flask-study/microblog/app/routes.py", line 46, in login
    user = User.query.filter_by(username=form.username.data).first()
  File "/Users/erickkendall/.pyenv/versions/3.10.2/envs/microblog/lib/python3.10/site-packages/sqlalchemy/orm/query.py", line 2728, in first
    return self.limit(1)._iter().first()  # type: ignore
  File "/Users/erickkendall/.pyenv/versions/3.10.2/envs/microblog/lib/python3.10/site-packages/sqlalchemy/orm/query.py", line 2827, in _iter
    result: Union[ScalarResult[_T], Result[_T]] = self.session.execute(
  File "/Users/erickkendall/.pyenv/versions/3.10.2/envs/microblog/lib/python3.10/site-packages/sqlalchemy/orm/session.py", line 2351, in execute
    return self._execute_internal(
  File "/Users/erickkendall/.pyenv/versions/3.10.2/envs/microblog/lib/python3.10/site-packages/sqlalchemy/orm/session.py", line 2236, in _execute_internal
    result: Result[Any] = compile_state_cls.orm_execute_statement(
  File "/Users/erickkendall/.pyenv/versions/3.10.2/envs/microblog/lib/python3.10/site-packages/sqlalchemy/orm/context.py", line 293, in orm_execute_statement
    result = conn.execute(
  File "/Users/erickkendall/.pyenv/versions/3.10.2/envs/microblog/lib/python3.10/site-packages/sqlalchemy/engine/base.py", line 1418, in execute
    return meth(
  File "/Users/erickkendall/.pyenv/versions/3.10.2/envs/microblog/lib/python3.10/site-packages/sqlalchemy/sql/elements.py", line 515, in _execute_on_connection
    return connection._execute_clauseelement(
  File "/Users/erickkendall/.pyenv/versions/3.10.2/envs/microblog/lib/python3.10/site-packages/sqlalchemy/engine/base.py", line 1640, in _execute_clauseelement
    ret = self._execute_context(
  File "/Users/erickkendall/.pyenv/versions/3.10.2/envs/microblog/lib/python3.10/site-packages/sqlalchemy/engine/base.py", line 1846, in _execute_context
    return self._exec_single_context(
  File "/Users/erickkendall/.pyenv/versions/3.10.2/envs/microblog/lib/python3.10/site-packages/sqlalchemy/engine/base.py", line 1986, in _exec_single_context
    self._handle_dbapi_exception(
  File "/Users/erickkendall/.pyenv/versions/3.10.2/envs/microblog/lib/python3.10/site-packages/sqlalchemy/engine/base.py", line 2353, in _handle_dbapi_exception
    raise sqlalchemy_exception.with_traceback(exc_info[2]) from e
  File "/Users/erickkendall/.pyenv/versions/3.10.2/envs/microblog/lib/python3.10/site-packages/sqlalchemy/engine/base.py", line 1967, in _exec_single_context
    self.dialect.do_execute(
  File "/Users/erickkendall/.pyenv/versions/3.10.2/envs/microblog/lib/python3.10/site-packages/sqlalchemy/engine/default.py", line 924, in do_execute
    cursor.execute(statement, parameters)
sqlalchemy.exc.OperationalError: (sqlite3.OperationalError) no such table: user
[SQL: SELECT user.id AS user_id, user.username AS user_username, user.email AS user_email, user.password_hash AS user_password_hash, user.about_me AS user_about_me, user.last_seen AS user_last_seen 
FROM user 
WHERE user.username = ?
 LIMIT ? OFFSET ?]
[parameters: ('sue', 1, 0)]
(Background on this error at: https://sqlalche.me/e/20/e3q8)
2024-07-12 11:19:54,544 INFO: Microblog startup [in /Users/erickkendall/Desktop/flask-study/microblog/app/__init__.py:44]
2024-07-12 11:19:58,497 INFO: Microblog startup [in /Users/erickkendall/Desktop/flask-study/microblog/app/__init__.py:44]
2024-07-12 11:20:14,499 INFO: Microblog startup [in /Users/erickkendall/Desktop/flask-study/microblog/app/__init__.py:44]
2024-07-12 11:20:24,562 ERROR: Exception on /login [POST] [in /Users/erickkendall/.pyenv/versions/3.10.2/envs/microblog/lib/python3.10/site-packages/flask/app.py:838]
Traceback (most recent call last):
  File "/Users/erickkendall/.pyenv/versions/3.10.2/envs/microblog/lib/python3.10/site-packages/sqlalchemy/engine/base.py", line 1967, in _exec_single_context
    self.dialect.do_execute(
  File "/Users/erickkendall/.pyenv/versions/3.10.2/envs/microblog/lib/python3.10/site-packages/sqlalchemy/engine/default.py", line 924, in do_execute
    cursor.execute(statement, parameters)
sqlite3.OperationalError: no such table: user

The above exception was the direct cause of the following exception:

Traceback (most recent call last):
  File "/Users/erickkendall/.pyenv/versions/3.10.2/envs/microblog/lib/python3.10/site-packages/flask/app.py", line 1473, in wsgi_app
    response = self.full_dispatch_request()
  File "/Users/erickkendall/.pyenv/versions/3.10.2/envs/microblog/lib/python3.10/site-packages/flask/app.py", line 882, in full_dispatch_request
    rv = self.handle_user_exception(e)
  File "/Users/erickkendall/.pyenv/versions/3.10.2/envs/microblog/lib/python3.10/site-packages/flask/app.py", line 880, in full_dispatch_request
    rv = self.dispatch_request()
  File "/Users/erickkendall/.pyenv/versions/3.10.2/envs/microblog/lib/python3.10/site-packages/flask/app.py", line 865, in dispatch_request
    return self.ensure_sync(self.view_functions[rule.endpoint])(**view_args)  # type: ignore[no-any-return]
  File "/Users/erickkendall/Desktop/flask-study/microblog/app/routes.py", line 46, in login
    user = User.query.filter_by(username=form.username.data).first()
  File "/Users/erickkendall/.pyenv/versions/3.10.2/envs/microblog/lib/python3.10/site-packages/sqlalchemy/orm/query.py", line 2728, in first
    return self.limit(1)._iter().first()  # type: ignore
  File "/Users/erickkendall/.pyenv/versions/3.10.2/envs/microblog/lib/python3.10/site-packages/sqlalchemy/orm/query.py", line 2827, in _iter
    result: Union[ScalarResult[_T], Result[_T]] = self.session.execute(
  File "/Users/erickkendall/.pyenv/versions/3.10.2/envs/microblog/lib/python3.10/site-packages/sqlalchemy/orm/session.py", line 2351, in execute
    return self._execute_internal(
  File "/Users/erickkendall/.pyenv/versions/3.10.2/envs/microblog/lib/python3.10/site-packages/sqlalchemy/orm/session.py", line 2236, in _execute_internal
    result: Result[Any] = compile_state_cls.orm_execute_statement(
  File "/Users/erickkendall/.pyenv/versions/3.10.2/envs/microblog/lib/python3.10/site-packages/sqlalchemy/orm/context.py", line 293, in orm_execute_statement
    result = conn.execute(
  File "/Users/erickkendall/.pyenv/versions/3.10.2/envs/microblog/lib/python3.10/site-packages/sqlalchemy/engine/base.py", line 1418, in execute
    return meth(
  File "/Users/erickkendall/.pyenv/versions/3.10.2/envs/microblog/lib/python3.10/site-packages/sqlalchemy/sql/elements.py", line 515, in _execute_on_connection
    return connection._execute_clauseelement(
  File "/Users/erickkendall/.pyenv/versions/3.10.2/envs/microblog/lib/python3.10/site-packages/sqlalchemy/engine/base.py", line 1640, in _execute_clauseelement
    ret = self._execute_context(
  File "/Users/erickkendall/.pyenv/versions/3.10.2/envs/microblog/lib/python3.10/site-packages/sqlalchemy/engine/base.py", line 1846, in _execute_context
    return self._exec_single_context(
  File "/Users/erickkendall/.pyenv/versions/3.10.2/envs/microblog/lib/python3.10/site-packages/sqlalchemy/engine/base.py", line 1986, in _exec_single_context
    self._handle_dbapi_exception(
  File "/Users/erickkendall/.pyenv/versions/3.10.2/envs/microblog/lib/python3.10/site-packages/sqlalchemy/engine/base.py", line 2353, in _handle_dbapi_exception
    raise sqlalchemy_exception.with_traceback(exc_info[2]) from e
  File "/Users/erickkendall/.pyenv/versions/3.10.2/envs/microblog/lib/python3.10/site-packages/sqlalchemy/engine/base.py", line 1967, in _exec_single_context
    self.dialect.do_execute(
  File "/Users/erickkendall/.pyenv/versions/3.10.2/envs/microblog/lib/python3.10/site-packages/sqlalchemy/engine/default.py", line 924, in do_execute
    cursor.execute(statement, parameters)
sqlalchemy.exc.OperationalError: (sqlite3.OperationalError) no such table: user
[SQL: SELECT user.id AS user_id, user.username AS user_username, user.email AS user_email, user.password_hash AS user_password_hash, user.about_me AS user_about_me, user.last_seen AS user_last_seen 
FROM user 
WHERE user.username = ?
 LIMIT ? OFFSET ?]
[parameters: ('ben', 1, 0)]
(Background on this error at: https://sqlalche.me/e/20/e3q8)
2024-07-12 11:20:39,086 INFO: Microblog startup [in /Users/erickkendall/Desktop/flask-study/microblog/app/__init__.py:44]
